Workbook
Name innsatu: #REF!
Name innsatu: #REF!
Name innsatu: #REF!
Name innsatu: #REF!
Name innsatu: #REF!
Name tourokusyubeytu: #REF!
Name tourokusyubeytu: #REF!
Name tourokusyubeytu: #REF!
Name tourokusyubeytu: #REF!
Name ｽｹｼﾞｭｰﾙ: #REF!
Name ｽｹｼﾞｭｰﾙ: #REF!
Name ｽｹｼﾞｭｰﾙ: #REF!
Name ｽｹｼﾞｭｰﾙ: #REF!
Name すけじゅーる: #REF!
Name すけじゅーる: #REF!
Name すけじゅーる: #REF!
Name すけじゅーる: #REF!
Name 印刷範囲: #REF!
Name 印刷範囲: #REF!
Name 印刷範囲: #REF!
Name 印刷範囲: #REF!
Name 印刷範囲２: #REF!
Name 印刷範囲２: #REF!
Name 印刷範囲２: #REF!
Name 印刷範囲２: #REF!
Name 印刷範囲３: #REF!
Name 印刷範囲３: #REF!
Name 印刷範囲３: #REF!
Name 印刷範囲３: #REF!
Name 印刷範囲４: #REF!
Name 印刷範囲４: #REF!
Name 印刷範囲４: #REF!
Name 印刷範囲４: #REF!
Name 印刷範囲5: #REF!
Name 印刷範囲5: #REF!
Name 印刷範囲5: #REF!
Name 印刷範囲5: #REF!
Name 御開扉時刻: [1]init!$J$4:$J$65536
Name 種別: #REF!
Name 種別: #REF!
Name 種別: #REF!
Name 種別: #REF!
Name 種別: #REF!
Name 宿坊計画２: #REF!
Name 宿坊計画２: #REF!
Name 宿坊計画２: #REF!
Name 宿坊計画２: #REF!
Name 宿坊計画２: #REF!
Name 地方部: #REF!
Name 地方部: #REF!
Name 地方部: #REF!
Name 地方部: #REF!
Name 地方部: #REF!
Name 登録種別: #REF!
Name 登録種別: #REF!
Name 登録種別: #REF!
Name 登録種別: #REF!
Name 登録種別: #REF!
Name 登録種別１: #REF!
Name 登録種別１: #REF!

Sheet 無線表まとめ
D1: 2026.7.17作成
H3: 無線表 | I3: 本体 | J3: 無線表 | K3: 本体
A4: 東1 | C4: 東18 | H4: 東１ | I4: 東１ | J4: 東18 | K4: 東18
A5: 東2 | C5: 東20 | H5: 東2 | I5: 東2 | J5: 東20 | K5: 東20
A6: 東3 | C6: 東21 | H6: 東3 | I6: 東3 | J6: 東21 | K6: 東21
A7: 東4 | C7: 東22 | H7: 東４ | I7: 東4 | J7: 東22 | K7: 東22
A8: 東5 | C8: 東23 | H8: 東５ | I8: 東5 | J8: 東23 | K8: 東23
A9: 東6 | C9: 東24 | H9: 東６ | I9: 東6 | J9: 東24 | K9: 東24
A10: 東7 | C10: 東25 | H10: 東７ | I10: 東7 | J10: 東25 | K10: 東25
A11: 東8 | C11: 東26 | H11: 東８ | I11: 東8 | J11: 東26 | K11: 東26
A12: 東9 | C12: 東27 | H12: 東９ | I12: 東9 | J12: 東27 | K12: 東27
A13: 東10 | C13: 東28 | H13: 東１０ | I13: 東10 | J13: 東28 | K13: 百けい12
A14: 東11 | C14: 東30 | H14: 東１１ | I14: 東11 | J14: 東30 | K14: 百けい13
A15: 東12 | C15: 東31 | H15: 東１２ | I15: 東12 | J15: 東31 | K15: 百けい14
... A20: 東17 | C20: 東36 | H20: 東１７ | I20: 東17 | J20: 東36 | K20: 東19
H23: 無線表 | I23: 本体 | J23: 無線表 | K23: 本体
A24: 百けい1 | C24: 百けい12 | H24: 百けい１ | I24: 百けい１ | J24: 百けい12 | K24: 東8
A25: 百けい2 | C25: 百けい13 | H25: 百けい2 | I25: 百けい2 | J25: 百けい13 | K25: 百けい17
A26: 百けい3 | C26: 百けい14 | H26: 百けい3 | I26: 百けい3 | J26: 百けい14 | K26: 東13
A27: 百けい4 | C27: 百けい15 | H27: 百けい４ | I27: 百けい4 | J27: 百けい15 | K27: 東18
A28: 百けい5 | C28: 百けい16 | H28: 百けい５ | I28: 百けい5 | J28: 百けい16 | K28: 東20
A29: 百けい6 | C29: 百けい19 | H29: 百けい６ | I29: 百けい6 | J29: 百けい19 | K29: 百けい19
A30: 百けい7 | H30: 百けい７ | I30: 百けい7
A31: 百けい8 | H31: 百けい８ | I31: 百けい8
A32: 百けい9 | H32: 百けい９ | I32: 百けい9
A33: 百けい10 | H33: 百けい１０ | I33: 百けい10
A34: 百けい11 | H34: 百けい１１ | I34: 百けい11
A38: №１ | B38: ×(不明) | C38: №９
A39: №２ | B39: ×(不明) | C39: №10
A40: №３ | B40: ×(不明) | C40: №11
A41: №４ | B41: ×(不明) | C41: №12 | D41: ×(故障)
A42: №５ | B42: ×(故障) | C42: №13 | D42: ×(故障)
A43: №６ | B43: ×(故障) | C43: №14 | D43: ×(故障)
A44: №７ | B44: ×(故障) | C44: №15 | D44: ×(故障)
A45: №８ | B45: ×(故障)

Sheet 東局(いじるな）
A1: =無線表まとめ!A3 -> 0 | F1: =$A$1 -> 0
A2: =無線表まとめ!A4 -> 東1 | B2: =無線表まとめ!B4 -> 0 | C2: =無線表まとめ!C4 -> 東18 | D2: =無線表まとめ!D4 -> 0 | F2: =$A2 -> 東1 | G2: =$B2 -> 0 | H2: =$C2 -> 東18 | I2: =$D2 -> 0
A3: =無線表まとめ!A5 -> 東2 | B3: =無線表まとめ!B5 -> 0 | C3: =無線表まとめ!C5 -> 東20 | D3: =無線表まとめ!D5 -> 0 | F3: =$A3 -> 東2 | G3: =$B3 -> 0 | H3: =$C3 -> 東20 | I3: =$D3 -> 0
A4: =無線表まとめ!A6 -> 東3 | B4: =無線表まとめ!B6 -> 0 | C4: =無線表まとめ!C6 -> 東21 | D4: =無線表まとめ!D6 -> 0 | F4: =$A4 -> 東3 | G4: =$B4 -> 0 | H4: =$C4 -> 東21 | I4: =$D4 -> 0
A5: =無線表まとめ!A7 -> 東4 | B5: =無線表まとめ!B7 -> 0 | C5: =無線表まとめ!C7 -> 東22 | D5: =無線表まとめ!D7 -> 0 | F5: =$A5 -> 東4 | G5: =$B5 -> 0 | H5: =$C5 -> 東22 | I5: =$D5 -> 0
A6: =無線表まとめ!A8 -> 東5 | B6: =無線表まとめ!B8 -> 0 | C6: =無線表まとめ!C8 -> 東23 | D6: =無線表まとめ!D8 -> 0 | F6: =$A6 -> 東5 | G6: =$B6 -> 0 | H6: =$C6 -> 東23 | I6: =$D6 -> 0
A7: =無線表まとめ!A9 -> 東6 | B7: =無線表まとめ!B9 -> 0 | C7: =無線表まとめ!C9 -> 東24 | D7: =無線表まとめ!D9 -> 0 | F7: =$A7 -> 東6 | G7: =$B7 -> 0 | H7: =$C7 -> 東24 | I7: =$D7 -> 0
A8: =無線表まとめ!A10 -> 東7 | B8: =無線表まとめ!B10 -> 0 | C8: =無線表まとめ!C10 -> 東25 | D8: =無線表まとめ!D10 -> 0 | F8: =$A8 -> 東7 | G8: =$B8 -> 0 | H8: =$C8 -> 東25 | I8: =$D8 -> 0
A9: =無線表まとめ!A11 -> 東8 | B9: =無線表まとめ!B11 -> 0 | C9: =無線表まとめ!C11 -> 東26 | D9: =無線表まとめ!D11 -> 0 | F9: =$A9 -> 東8 | G9: =$B9 -> 0 | H9: =$C9 -> 東26 | I9: =$D9 -> 0
A10: =無線表まとめ!A12 -> 東9 | B10: =無線表まとめ!B12 -> 0 | C10: =無線表まとめ!C12 -> 東27 | D10: =無線表まとめ!D12 -> 0 | F10: =$A10 -> 東9 | G10: =$B10 -> 0 | H10: =$C10 -> 東27 | I10: =$D10 -> 0
A11: =無線表まとめ!A13 -> 東10 | B11: =無線表まとめ!B13 -> 0 | C11: =無線表まとめ!C13 -> 東28 | D11: =無線表まとめ!D13 -> 0 | F11: =$A11 -> 東10 | G11: =$B11 -> 0 | H11: =$C11 -> 東28 | I11: =$D11 -> 0
A12: =無線表まとめ!A14 -> 東11 | B12: =無線表まとめ!B14 -> 0 | C12: =無線表まとめ!C14 -> 東30 | D12: =無線表まとめ!D14 -> 0 | F12: =$A12 -> 東11 | G12: =$B12 -> 0 | H12: =$C12 -> 東30 | I12: =$D12 -> 0
A13: =無線表まとめ!A15 -> 東12 | B13: =無線表まとめ!B15 -> 0 | C13: =無線表まとめ!C15 -> 東31 | D13: =無線表まとめ!D15 -> 0 | F13: =$A13 -> 東12 | G13: =$B13 -> 0 | H13: =$C13 -> 東31 | I13: =$D13 -> 0
... A18: =無線表まとめ!A20 -> 東17 | B18: =無線表まとめ!B20 -> 0 | C18: =無線表まとめ!C20 -> 東36 | D18: =無線表まとめ!D20 -> 0 | F18: =$A18 -> 東17 | G18: =$B18 -> 0 | H18: =$C18 -> 東36 | I18: =$D18 -> 0
A20: =$A$1 -> 0 | F20: =$A$1 -> 0
A21: =$A$2 -> 東1 | B21: =$B$2 -> 0 | C21: =$C$2 -> 東18 | D21: =$D$2 -> 0 | F21: =$A$2 -> 東1 | G21: =$B$2 -> 0 | H21: =$C$2 -> 東18 | I21: =$D$2 -> 0
A22: =$A$3 -> 東2 | B22: =$B$3 -> 0 | C22: =$C$3 -> 東20 | D22: =$D$3 -> 0 | F22: =$A$3 -> 東2 | G22: =$B$3 -> 0 | H22: =$C$3 -> 東20 | I22: =$D$3 -> 0
A23: =$A$4 -> 東3 | B23: =$B$4 -> 0 | C23: =$C$4 -> 東21 | D23: =$D$4 -> 0 | F23: =$A$4 -> 東3 | G23: =$B$4 -> 0 | H23: =$C$4 -> 東21 | I23: =$D$4 -> 0
A24: =$A$5 -> 東4 | B24: =$B$5 -> 0 | C24: =$C$5 -> 東22 | D24: =$D$5 -> 0 | F24: =$A$5 -> 東4 | G24: =$B$5 -> 0 | H24: =$C$5 -> 東22 | I24: =$D$5 -> 0
A25: =$A$6 -> 東5 | B25: =$B$6 -> 0 | C25: =$C$6 -> 東23 | D25: =$D$6 -> 0 | F25: =$A$6 -> 東5 | G25: =$B$6 -> 0 | H25: =$C$6 -> 東23 | I25: =$D$6 -> 0
A26: =$A$7 -> 東6 | B26: =$B$7 -> 0 | C26: =$C$7 -> 東24 | D26: =$D$7 -> 0 | F26: =$A$7 -> 東6 | G26: =$B$7 -> 0 | H26: =$C$7 -> 東24 | I26: =$D$7 -> 0
A27: =$A$8 -> 東7 | B27: =$B$8 -> 0 | C27: =$C$8 -> 東25 | D27: =$D$8 -> 0 | F27: =$A$8 -> 東7 | G27: =$B$8 -> 0 | H27: =$C$8 -> 東25 | I27: =$D$8 -> 0
A28: =$A$9 -> 東8 | B28: =$B$9 -> 0 | C28: =$C$9 -> 東26 | D28: =$D$9 -> 0 | F28: =$A$9 -> 東8 | G28: =$B$9 -> 0 | H28: =$C$9 -> 東26 | I28: =$D$9 -> 0
A29: =$A$10 -> 東9 | B29: =$B$10 -> 0 | C29: =$C$10 -> 東27 | D29: =$D$10 -> 0 | F29: =$A$10 -> 東9 | G29: =$B$10 -> 0 | H29: =$C$10 -> 東27 | I29: =$D$10 -> 0
A30: =$A$11 -> 東10 | B30: =$B$11 -> 0 | C30: =$C$11 -> 東28 | D30: =$D$11 -> 0 | F30: =$A$11 -> 東10 | G30: =$B$11 -> 0 | H30: =$C$11 -> 東28 | I30: =$D$11 -> 0
A31: =$A$12 -> 東11 | B31: =$B$12 -> 0 | C31: =$C$12 -> 東30 | D31: =$D$12 -> 0 | F31: =$A$12 -> 東11 | G31: =$B$12 -> 0 | H31: =$C$12 -> 東30 | I31: =$D$12 -> 0
A32: =$A$13 -> 東12 | B32: =$B$13 -> 0 | C32: =$C$13 -> 東31 | D32: =$D$13 -> 0 | F32: =$A$13 -> 東12 | G32: =$B$13 -> 0 | H32: =$C$13 -> 東31 | I32: =$D$13 -> 0
A33: =$A$14 -> 東13 | B33: =$B$14 -> 0 | C33: =$C$14 -> 東32 | D33: =$D$14 -> 0 | F33: =$A$14 -> 東13 | G33: =$B$14 -> 0 | H33: =$C$14 -> 東32 | I33: =$D$14 -> 0
A34: =$A$15 -> 東14 | B34: =$B$15 -> 0 | C34: =$C$15 -> 東33 | D34: =$D$15 -> 0 | F34: =$A$15 -> 東14 | G34: =$B$15 -> 0 | H34: =$C$15 -> 東33 | I34: =$D$15 -> 0
A35: =$A$16 -> 東15 | B35: =$B$16 -> 0 | C35: =$C$16 -> 東34 | D35: =$D$16 -> 0 | F35: =$A$16 -> 東15 | G35: =$B$16 -> 0 | H35: =$C$16 -> 東34 | I35: =$D$16 -> 0
A36: =$A$17 -> 東16 | B36: =$B$17 -> 0 | C36: =$C$17 -> 東35 | D36: =$D$17 -> 0 | F36: =$A$17 -> 東16 | G36: =$B$17 -> 0 | H36: =$C$17 -> 東35 | I36: =$D$17 -> 0
A37: =$A$18 -> 東17 | B37: =$B$18 -> 0 | C37: =$C$18 -> 東36 | D37: =$D$18 -> 0 | F37: =$A$18 -> 東17 | G37: =$B$18 -> 0 | H37: =$C$18 -> 東36 | I37: =$D$18 -> 0
A39: =$A$1 -> 0 | F39: =$A$1 -> 0
A40: =$A$2 -> 東1 | B40: =$B$2 -> 0 | C40: =$C$2 -> 東18 | D40: =$D$2 -> 0 | F40: =$A$2 -> 東1 | G40: =$B$2 -> 0 | H40: =$C$2 -> 東18 | I40: =$D$2 -> 0
A41: =$A$3 -> 東2 | B41: =$B$3 -> 0 | C41: =$C$3 -> 東20 | D41: =$D$3 -> 0 | F41: =$A$3 -> 東2 | G41: =$B$3 -> 0 | H41: =$C$3 -> 東20 | I41: =$D$3 -> 0
A42: =$A$4 -> 東3 | B42: =$B$4 -> 0 | C42: =$C$4 -> 東21 | D42: =$D$4 -> 0 | F42: =$A$4 -> 東3 | G42: =$B$4 -> 0 | H42: =$C$4 -> 東21 | I42: =$D$4 -> 0
A43: =$A$5 -> 東4 | B43: =$B$5 -> 0 | C43: =$C$5 -> 東22 | D43: =$D$5 -> 0 | F43: =$A$5 -> 東4 | G43: =$B$5 -> 0 | H43: =$C$5 -> 東22 | I43: =$D$5 -> 0
A44: =$A$6 -> 東5 | B44: =$B$6 -> 0 | C44: =$C$6 -> 東23 | D44: =$D$6 -> 0 | F44: =$A$6 -> 東5 | G44: =$B$6 -> 0 | H44: =$C$6 -> 東23 | I44: =$D$6 -> 0
A45: =$A$7 -> 東6 | B45: =$B$7 -> 0 | C45: =$C$7 -> 東24 | D45: =$D$7 -> 0 | F45: =$A$7 -> 東6 | G45: =$B$7 -> 0 | H45: =$C$7 -> 東24 | I45: =$D$7 -> 0
A46: =$A$8 -> 東7 | B46: =$B$8 -> 0 | C46: =$C$8 -> 東25 | D46: =$D$8 -> 0 | F46: =$A$8 -> 東7 | G46: =$B$8 -> 0 | H46: =$C$8 -> 東25 | I46: =$D$8 -> 0
...

Sheet 百けい（いじるな）
A1: =無線表まとめ!A22 -> 0 | F1: =$A$1 -> 0
A2: =無線表まとめ!A23 -> 0 | C2: =無線表まとめ!C23 -> 0 | F2: =$A$2 -> 0 | H2: =$C$2 -> 0
A3: =無線表まとめ!A24 -> 百けい1 | B3: =無線表まとめ!B24 -> 0 | C3: =無線表まとめ!C24 -> 百けい12 | D3: =無線表まとめ!D24 -> 0 | F3: =$A$3 -> 百けい1 | G3: =$B$3 -> 0 | H3: =$C$3 -> 百けい12 | I3: =$D$3 -> 0
A4: =無線表まとめ!A25 -> 百けい2 | B4: =無線表まとめ!B25 -> 0 | C4: =無線表まとめ!C25 -> 百けい13 | D4: =無線表まとめ!D25 -> 0 | F4: =$A$4 -> 百けい2 | G4: =$B$4 -> 0 | H4: =$C$4 -> 百けい13 | I4: =$D$4 -> 0
A5: =無線表まとめ!A27 -> 百けい4 | B5: =無線表まとめ!B27 -> 0 | C5: =無線表まとめ!C26 -> 百けい14 | D5: =無線表まとめ!D26 -> 0 | F5: =$A$5 -> 百けい4 | G5: =$B$5 -> 0 | H5: =$C$5 -> 百けい14 | I5: =$D$5 -> 0
A6: =無線表まとめ!A28 -> 百けい5 | B6: =無線表まとめ!B28 -> 0 | C6: =無線表まとめ!C27 -> 百けい15 | D6: =無線表まとめ!D27 -> 0 | F6: =$A$6 -> 百けい5 | G6: =$B$6 -> 0 | H6: =$C$6 -> 百けい15 | I6: =$D$6 -> 0
A7: =無線表まとめ!A29 -> 百けい6 | B7: =無線表まとめ!B29 -> 0 | C7: =無線表まとめ!C28 -> 百けい16 | D7: =無線表まとめ!D28 -> 0 | F7: =$A$7 -> 百けい6 | G7: =$B$7 -> 0 | H7: =$C$7 -> 百けい16 | I7: =$D$7 -> 0
A8: =無線表まとめ!A30 -> 百けい7 | B8: =無線表まとめ!B30 -> 0 | C8: =無線表まとめ!C29 -> 百けい19 | D8: =無線表まとめ!D29 -> 0 | F8: =$A$8 -> 百けい7 | G8: =$B$8 -> 0 | H8: =$C$8 -> 百けい19 | I8: =$D$8 -> 0
A9: =無線表まとめ!A31 -> 百けい8 | B9: =無線表まとめ!B31 -> 0 | C9: =無線表まとめ!C30 -> 0 | D9: =無線表まとめ!D31 -> 0 | F9: =$A$9 -> 百けい8 | G9: =$B$9 -> 0 | H9: =$C$9 -> 0 | I9: =$D$9 -> 0
A10: =無線表まとめ!A32 -> 百けい9 | B10: =無線表まとめ!B32 -> 0 | C10: =無線表まとめ!C31 -> 0 | D10: =無線表まとめ!D32 -> 0 | F10: =$A$10 -> 百けい9 | G10: =$B$10 -> 0 | H10: =$C$10 -> 0 | I10: =$D$10 -> 0
A11: =無線表まとめ!A33 -> 百けい10 | B11: =無線表まとめ!B33 -> 0 | F11: =$A$11 -> 百けい10 | G11: =$B$11 -> 0 | H11: =$C$11 -> 0 | I11: =$D$11 -> 0
A12: =無線表まとめ!A26 -> 百けい3 | B12: =無線表まとめ!B26 -> 0 | F12: =$A$12 -> 百けい3 | G12: =$B$12 -> 0
A13: =無線表まとめ!A34 -> 百けい11 | B13: =無線表まとめ!B34 -> 0 | C13: =無線表まとめ!C34 -> 0 | D13: =無線表まとめ!D34 -> 0 | F13: =$A$13 -> 百けい11 | G13: =$B$13 -> 0 | H13: =$C$13 -> 0 | I13: =$D$13 -> 0
A15: =$A$1 -> 0 | F15: =$A$1 -> 0
A16: =$A$2 -> 0 | C16: =$C$2 -> 0 | F16: =$A$2 -> 0 | H16: =$C$2 -> 0
A17: =$A$3 -> 百けい1 | B17: =$B$3 -> 0 | C17: =$C$3 -> 百けい12 | D17: =$D$3 -> 0 | F17: =$A$3 -> 百けい1 | G17: =$B$3 -> 0 | H17: =$C$3 -> 百けい12 | I17: =$D$3 -> 0
A18: =$A$4 -> 百けい2 | B18: =$B$4 -> 0 | C18: =$C$4 -> 百けい13 | D18: =$D$4 -> 0 | F18: =$A$4 -> 百けい2 | G18: =$B$4 -> 0 | H18: =$C$4 -> 百けい13 | I18: =$D$4 -> 0
A19: =$A$5 -> 百けい4 | B19: =$B$5 -> 0 | C19: =$C$5 -> 百けい14 | D19: =$D$5 -> 0 | F19: =$A$5 -> 百けい4 | G19: =$B$5 -> 0 | H19: =$C$5 -> 百けい14 | I19: =$D$5 -> 0
A20: =$A$6 -> 百けい5 | B20: =$B$6 -> 0 | C20: =$C$6 -> 百けい15 | D20: =$D$6 -> 0 | F20: =$A$6 -> 百けい5 | G20: =$B$6 -> 0 | H20: =$C$6 -> 百けい15 | I20: =$D$6 -> 0
A21: =$A$7 -> 百けい6 | B21: =$B$7 -> 0 | C21: =$C$7 -> 百けい16 | D21: =$D$7 -> 0 | F21: =$A$7 -> 百けい6 | G21: =$B$7 -> 0 | H21: =$C$7 -> 百けい16 | I21: =$D$7 -> 0
A22: =$A$8 -> 百けい7 | B22: =$B$8 -> 0 | C22: =$C$8 -> 百けい19 | D22: =$D$8 -> 0 | F22: =$A$8 -> 百けい7 | G22: =$B$8 -> 0 | H22: =$C$8 -> 百けい19 | I22: =$D$8 -> 0
A23: =$A$9 -> 百けい8 | B23: =$B$9 -> 0 | C23: =$C$9 -> 0 | D23: =$D$9 -> 0 | F23: =$A$9 -> 百けい8 | G23: =$B$9 -> 0 | H23: =$C$9 -> 0 | I23: =$D$9 -> 0
A24: =$A$10 -> 百けい9 | B24: =$B$10 -> 0 | C24: =$C$10 -> 0 | D24: =$D$10 -> 0 | F24: =$A$10 -> 百けい9 | G24: =$B$10 -> 0 | H24: =$C$10 -> 0 | I24: =$D$10 -> 0
A25: =$A$11 -> 百けい10 | B25: =$B$11 -> 0 | C25: =$C$11 -> 0 | D25: =$D$11 -> 0 | F25: =$A$11 -> 百けい10 | G25: =$B$11 -> 0 | H25: =$C$11 -> 0 | I25: =$D$11 -> 0
A26: =$A$12 -> 百けい3 | B26: =$B$12 -> 0 | F26: =$A$12 -> 百けい3 | G26: =$B$12 -> 0
A27: =$A$13 -> 百けい11 | B27: =$B$13 -> 0 | C27: =$C$13 -> 0 | D27: =$D$13 -> 0 | F27: =$A$13 -> 百けい11 | G27: =$B$13 -> 0 | H27: =$C$13 -> 0 | I27: =$D$13 -> 0
A29: =$A$1 -> 0 | F29: =$A$1 -> 0
A30: =$A$2 -> 0 | C30: =$C$2 -> 0 | F30: =$A$2 -> 0 | H30: =$C$2 -> 0
A31: =$A$3 -> 百けい1 | B31: =$B$3 -> 0 | C31: =$C$3 -> 百けい12 | D31: =$D$3 -> 0 | F31: =$A$3 -> 百けい1 | G31: =$B$3 -> 0 | H31: =$C$3 -> 百けい12 | I31: =$D$3 -> 0
A32: =$A$4 -> 百けい2 | B32: =$B$4 -> 0 | C32: =$C$4 -> 百けい13 | D32: =$D$4 -> 0 | F32: =$A$4 -> 百けい2 | G32: =$B$4 -> 0 | H32: =$C$4 -> 百けい13 | I32: =$D$4 -> 0
A33: =$A$5 -> 百けい4 | B33: =$B$5 -> 0 | C33: =$C$5 -> 百けい14 | D33: =$D$5 -> 0 | F33: =$A$5 -> 百けい4 | G33: =$B$5 -> 0 | H33: =$C$5 -> 百けい14 | I33: =$D$5 -> 0
A34: =$A$6 -> 百けい5 | B34: =$B$6 -> 0 | C34: =$C$6 -> 百けい15 | D34: =$D$6 -> 0 | F34: =$A$6 -> 百けい5 | G34: =$B$6 -> 0 | H34: =$C$6 -> 百けい15 | I34: =$D$6 -> 0
A35: =$A$7 -> 百けい6 | B35: =$B$7 -> 0 | C35: =$C$7 -> 百けい16 | D35: =$D$7 -> 0 | F35: =$A$7 -> 百けい6 | G35: =$B$7 -> 0 | H35: =$C$7 -> 百けい16 | I35: =$D$7 -> 0
A36: =$A$8 -> 百けい7 | B36: =$B$8 -> 0 | C36: =$C$8 -> 百けい19 | D36: =$D$8 -> 0 | F36: =$A$8 -> 百けい7 | G36: =$B$8 -> 0 | H36: =$C$8 -> 百けい19 | I36: =$D$8 -> 0
A37: =$A$9 -> 百けい8 | B37: =$B$9 -> 0 | C37: =$C$9 -> 0 | D37: =$D$9 -> 0 | F37: =$A$9 -> 百けい8 | G37: =$B$9 -> 0 | H37: =$C$9 -> 0 | I37: =$D$9 -> 0
A38: =$A$10 -> 百けい9 | B38: =$B$10 -> 0 | C38: =$C$10 -> 0 | D38: =$D$10 -> 0 | F38: =$A$10 -> 百けい9 | G38: =$B$10 -> 0 | H38: =$C$10 -> 0 | I38: =$D$10 -> 0
A39: =$A$11 -> 百けい10 | B39: =$B$11 -> 0 | C39: =$C$11 -> 0 | D39: =$D$11 -> 0 | F39: =$A$11 -> 百けい10 | G39: =$B$11 -> 0 | H39: =$C$11 -> 0 | I39: =$D$11 -> 0
A40: =$A$12 -> 百けい3 | B40: =$B$12 -> 0 | F40: =$A$12 -> 百けい3 | G40: =$B$12 -> 0
A41: =$A$13 -> 百けい11 | B41: =$B$13 -> 0 | C41: =$C$13 -> 0 | D41: =$D$13 -> 0 | F41: =$A$13 -> 百けい11 | G41: =$B$13 -> 0 | H41: =$C$13 -> 0 | I41: =$D$13 -> 0
A43: =$A$1 -> 0 | F43: =$A$1 -> 0
...

Sheet 省電力（いじるな）
B1: =無線表まとめ!A36 -> 0 | G1: =$B$1 -> 0
C2: 省電力 | E2: 省電力 | G2: =$B$2 -> 0 | H2: =$C$2 -> 省電力 | I2: =$D$2 -> 0 | J2: =$E$2 -> 省電力
B3: =無線表まとめ!A38 -> №１ | C3: =無線表まとめ!B38 -> ×(不明) | D3: =無線表まとめ!C38 -> №９ | E3: =無線表まとめ!D38 -> 0 | G3: =$B$3 -> №１ | H3: =$C$3 -> ×(不明) | I3: =$D$3 -> №９ | J3: =$E$3 -> 0
B4: =無線表まとめ!A39 -> №２ | C4: =無線表まとめ!B39 -> ×(不明) | D4: =無線表まとめ!C39 -> №10 | E4: =無線表まとめ!D39 -> 0 | G4: =$B$4 -> №２ | H4: =$C$4 -> ×(不明) | I4: =$D$4 -> №10 | J4: =$E$4 -> 0
B5: =無線表まとめ!A40 -> №３ | C5: =無線表まとめ!B40 -> ×(不明) | D5: =無線表まとめ!C40 -> №11 | E5: =無線表まとめ!D40 -> 0 | G5: =$B$5 -> №３ | H5: =$C$5 -> ×(不明) | I5: =$D$5 -> №11 | J5: =$E$5 -> 0
B6: =無線表まとめ!A41 -> №４ | C6: =無線表まとめ!B41 -> ×(不明) | D6: =無線表まとめ!C41 -> №12 | E6: =無線表まとめ!D41 -> ×(故障) | G6: =$B$6 -> №４ | H6: =$C$6 -> ×(不明) | I6: =$D$6 -> №12 | J6: =$E$6 -> ×(故障)
B7: =無線表まとめ!A42 -> №５ | C7: =無線表まとめ!B42 -> ×(故障) | D7: =無線表まとめ!C42 -> №13 | E7: =無線表まとめ!D42 -> ×(故障) | G7: =$B$7 -> №５ | H7: =$C$7 -> ×(故障) | I7: =$D$7 -> №13 | J7: =$E$7 -> ×(故障)
B8: =無線表まとめ!A43 -> №６ | C8: =無線表まとめ!B43 -> ×(故障) | D8: =無線表まとめ!C43 -> №14 | E8: =無線表まとめ!D43 -> ×(故障) | G8: =$B$8 -> №６ | H8: =$C$8 -> ×(故障) | I8: =$D$8 -> №14 | J8: =$E$8 -> ×(故障)
B9: =無線表まとめ!A44 -> №７ | C9: =無線表まとめ!B44 -> ×(故障) | D9: =無線表まとめ!C44 -> №15 | E9: =無線表まとめ!D44 -> ×(故障) | G9: =$B$9 -> №７ | H9: =$C$9 -> ×(故障) | I9: =$D$9 -> №15 | J9: =$E$9 -> ×(故障)
B10: =無線表まとめ!A45 -> №８ | C10: =無線表まとめ!B45 -> ×(故障) | D10: =無線表まとめ!C45 -> 0 | E10: =無線表まとめ!D45 | G10: =$B$10 -> №８ | H10: =$C$10 -> ×(故障) | I10: =$D$10 -> 0 | J10: =$E$10
B12: =$B$1 -> 0 | G12: =$B$1 -> 0
B13: =$B$2 -> 0 | C13: =$C$2 -> 省電力 | D13: =$D$2 -> 0 | E13: =$E$2 -> 省電力 | G13: =$B$2 -> 0 | H13: =$C$2 -> 省電力 | I13: =$D$2 -> 0 | J13: =$E$2 -> 省電力
B14: =$B$3 -> №１ | C14: =$C$3 -> ×(不明) | D14: =$D$3 -> №９ | E14: =$E$3 -> 0 | G14: =$B$3 -> №１ | H14: =$C$3 -> ×(不明) | I14: =$D$3 -> №９ | J14: =$E$3 -> 0
B15: =$B$4 -> №２ | C15: =$C$4 -> ×(不明) | D15: =$D$4 -> №10 | E15: =$E$4 -> 0 | G15: =$B$4 -> №２ | H15: =$C$4 -> ×(不明) | I15: =$D$4 -> №10 | J15: =$E$4 -> 0
B16: =$B$5 -> №３ | C16: =$C$5 -> ×(不明) | D16: =$D$5 -> №11 | E16: =$E$5 -> 0 | G16: =$B$5 -> №３ | H16: =$C$5 -> ×(不明) | I16: =$D$5 -> №11 | J16: =$E$5 -> 0
B17: =$B$6 -> №４ | C17: =$C$6 -> ×(不明) | D17: =$D$6 -> №12 | E17: =$E$6 -> ×(故障) | G17: =$B$6 -> №４ | H17: =$C$6 -> ×(不明) | I17: =$D$6 -> №12 | J17: =$E$6 -> ×(故障)
B18: =$B$7 -> №５ | C18: =$C$7 -> ×(故障) | D18: =$D$7 -> №13 | E18: =$E$7 -> ×(故障) | G18: =$B$7 -> №５ | H18: =$C$7 -> ×(故障) | I18: =$D$7 -> №13 | J18: =$E$7 -> ×(故障)
B19: =$B$8 -> №６ | C19: =$C$8 -> ×(故障) | D19: =$D$8 -> №14 | E19: =$E$8 -> ×(故障) | G19: =$B$8 -> №６ | H19: =$C$8 -> ×(故障) | I19: =$D$8 -> №14 | J19: =$E$8 -> ×(故障)
B20: =$B$9 -> №７ | C20: =$C$9 -> ×(故障) | D20: =$D$9 -> №15 | E20: =$E$9 -> ×(故障) | G20: =$B$9 -> №７ | H20: =$C$9 -> ×(故障) | I20: =$D$9 -> №15 | J20: =$E$9 -> ×(故障)
B21: =$B$10 -> №８ | C21: =$C$10 -> ×(故障) | D21: =$D$10 -> 0 | E21: =$E$10 | G21: =$B$10 -> №８ | H21: =$C$10 -> ×(故障) | I21: =$D$10 -> 0 | J21: =$E$10
B23: =$B$1 -> 0 | G23: =$B$1 -> 0
B24: =$B$2 -> 0 | C24: =$C$2 -> 省電力 | D24: =$D$2 -> 0 | E24: =$E$2 -> 省電力 | G24: =$B$2 -> 0 | H24: =$C$2 -> 省電力 | I24: =$D$2 -> 0 | J24: =$E$2 -> 省電力
B25: =$B$3 -> №１ | C25: =$C$3 -> ×(不明) | D25: =$D$3 -> №９ | E25: =$E$3 -> 0 | G25: =$B$3 -> №１ | H25: =$C$3 -> ×(不明) | I25: =$D$3 -> №９ | J25: =$E$3 -> 0
B26: =$B$4 -> №２ | C26: =$C$4 -> ×(不明) | D26: =$D$4 -> №10 | E26: =$E$4 -> 0 | G26: =$B$4 -> №２ | H26: =$C$4 -> ×(不明) | I26: =$D$4 -> №10 | J26: =$E$4 -> 0
B27: =$B$5 -> №３ | C27: =$C$5 -> ×(不明) | D27: =$D$5 -> №11 | E27: =$E$5 -> 0 | G27: =$B$5 -> №３ | H27: =$C$5 -> ×(不明) | I27: =$D$5 -> №11 | J27: =$E$5 -> 0
B28: =$B$6 -> №４ | C28: =$C$6 -> ×(不明) | D28: =$D$6 -> №12 | E28: =$E$6 -> ×(故障) | G28: =$B$6 -> №４ | H28: =$C$6 -> ×(不明) | I28: =$D$6 -> №12 | J28: =$E$6 -> ×(故障)
B29: =$B$7 -> №５ | C29: =$C$7 -> ×(故障) | D29: =$D$7 -> №13 | E29: =$E$7 -> ×(故障) | G29: =$B$7 -> №５ | H29: =$C$7 -> ×(故障) | I29: =$D$7 -> №13 | J29: =$E$7 -> ×(故障)
B30: =$B$8 -> №６ | C30: =$C$8 -> ×(故障) | D30: =$D$8 -> №14 | E30: =$E$8 -> ×(故障) | G30: =$B$8 -> №６ | H30: =$C$8 -> ×(故障) | I30: =$D$8 -> №14 | J30: =$E$8 -> ×(故障)
B31: =$B$9 -> №７ | C31: =$C$9 -> ×(故障) | D31: =$D$9 -> №15 | E31: =$E$9 -> ×(故障) | G31: =$B$9 -> №７ | H31: =$C$9 -> ×(故障) | I31: =$D$9 -> №15 | J31: =$E$9 -> ×(故障)
B32: =$B$10 -> №８ | C32: =$C$10 -> ×(故障) | D32: =$D$10 -> 0 | E32: =$E$10 | G32: =$B$10 -> №８ | H32: =$C$10 -> ×(故障) | I32: =$D$10 -> 0 | J32: =$E$10
B34: =$B$1 -> 0 | G34: =$B$1 -> 0
B35: =$B$2 -> 0 | C35: =$C$2 -> 省電力 | D35: =$D$2 -> 0 | E35: =$E$2 -> 省電力 | G35: =$B$2 -> 0 | H35: =$C$2 -> 省電力 | I35: =$D$2 -> 0 | J35: =$E$2 -> 省電力
B36: =$B$3 -> №１ | C36: =$C$3 -> ×(不明) | D36: =$D$3 -> №９ | E36: =$E$3 -> 0 | G36: =$B$3 -> №１ | H36: =$C$3 -> ×(不明) | I36: =$D$3 -> №９ | J36: =$E$3 -> 0
B37: =$B$4 -> №２ | C37: =$C$4 -> ×(不明) | D37: =$D$4 -> №10 | E37: =$E$4 -> 0 | G37: =$B$4 -> №２ | H37: =$C$4 -> ×(不明) | I37: =$D$4 -> №10 | J37: =$E$4 -> 0
B38: =$B$5 -> №３ | C38: =$C$5 -> ×(不明) | D38: =$D$5 -> №11 | E38: =$E$5 -> 0 | G38: =$B$5 -> №３ | H38: =$C$5 -> ×(不明) | I38: =$D$5 -> №11 | J38: =$E$5 -> 0
B39: =$B$6 -> №４ | C39: =$C$6 -> ×(不明) | D39: =$D$6 -> №12 | E39: =$E$6 -> ×(故障) | G39: =$B$6 -> №４ | H39: =$C$6 -> ×(不明) | I39: =$D$6 -> №12 | J39: =$E$6 -> ×(故障)
B40: =$B$7 -> №５ | C40: =$C$7 -> ×(故障) | D40: =$D$7 -> №13 | E40: =$E$7 -> ×(故障) | G40: =$B$7 -> №５ | H40: =$C$7 -> ×(故障) | I40: =$D$7 -> №13 | J40: =$E$7 -> ×(故障)
B41: =$B$8 -> №６ | C41: =$C$8 -> ×(故障) | D41: =$D$8 -> №14 | E41: =$E$8 -> ×(故障) | G41: =$B$8 -> №６ | H41: =$C$8 -> ×(故障) | I41: =$D$8 -> №14 | J41: =$E$8 -> ×(故障)
B42: =$B$9 -> №７ | C42: =$C$9 -> ×(故障) | D42: =$D$9 -> №15 | E42: =$E$9 -> ×(故障) | G42: =$B$9 -> №７ | H42: =$C$9 -> ×(故障) | I42: =$D$9 -> №15 | J42: =$E$9 -> ×(故障)
B43: =$B$10 -> №８ | C43: =$C$10 -> ×(故障) | D43: =$D$10 -> 0 | E43: =$E$10 | G43: =$B$10 -> №８ | H43: =$C$10 -> ×(故障) | I43: =$D$10 -> 0 | J43: =$E$10
...
